Building DAG of jobs...
shared_storage_local_copies: True
remote_exec: False
Using shell: /usr/bin/bash
Provided cores: 24
Rules claiming more threads will be scaled down.
Conda environments: ignored
Job stats:
job                 count
----------------  -------
all                     1
infer_experiment        6
total                   7

Resources before job selection: {'_cores': 24, '_nodes': 9223372036854775807}
Ready jobs (6)
Select jobs to execute...
Selected jobs (6)
Resources after job selection: {'_cores': 18, '_nodes': 9223372036854775801}
Execute 6 jobs...

[Mon Aug 19 00:40:31 2024]
Job 75: RAP1_REP1_treatment: Running Infer experiment
Reason: Missing output files: results/infer_experiment/RAP1_REP1_treatment/RAP1_REP1_treatment.infer_experiment.txt


[Mon Aug 19 00:40:31 2024]
Job 77: RAP1_REP3_treatment: Running Infer experiment
Reason: Missing output files: results/infer_experiment/RAP1_REP3_treatment/RAP1_REP3_treatment.infer_experiment.txt


[Mon Aug 19 00:40:31 2024]
Job 76: RAP1_REP2_treatment: Running Infer experiment
Reason: Missing output files: results/infer_experiment/RAP1_REP2_treatment/RAP1_REP2_treatment.infer_experiment.txt

Full Traceback (most recent call last):
  File "/home/lucianhu/micromamba/envs/rna_snakemake/lib/python3.12/site-packages/snakemake/executors/local.py", line 423, in run_wrapper
    run(
  File "/home/lucianhu/rna_snakemake/test_ting/Snakefile", line 1403, in __rule_infer_experiment
  File "/home/lucianhu/micromamba/envs/rna_snakemake/lib/python3.12/site-packages/snakemake/shell.py", line 357, in __new__
    raise sp.CalledProcessError(retcode, cmd)
subprocess.CalledProcessError: Command 'set -euo pipefail;  
        infer_experiment.py -i results/align/bam_markup/RAP1_REP1_treatment/RAP1_REP1_treatment.markdup.sorted.bam -r resources/annotation.filtered.bed > results/infer_experiment/RAP1_REP1_treatment/RAP1_REP1_treatment.infer_experiment.txt 2>' returned non-zero exit status 2.

Full Traceback (most recent call last):
  File "/home/lucianhu/micromamba/envs/rna_snakemake/lib/python3.12/site-packages/snakemake/executors/local.py", line 423, in run_wrapper
    run(
  File "/home/lucianhu/rna_snakemake/test_ting/Snakefile", line 1403, in __rule_infer_experiment
  File "/home/lucianhu/micromamba/envs/rna_snakemake/lib/python3.12/site-packages/snakemake/shell.py", line 357, in __new__
    raise sp.CalledProcessError(retcode, cmd)
subprocess.CalledProcessError: Command 'set -euo pipefail;  
        infer_experiment.py -i results/align/bam_markup/RAP1_REP3_treatment/RAP1_REP3_treatment.markdup.sorted.bam -r resources/annotation.filtered.bed > results/infer_experiment/RAP1_REP3_treatment/RAP1_REP3_treatment.infer_experiment.txt 2>' returned non-zero exit status 2.


Full Traceback (most recent call last):
  File "/home/lucianhu/micromamba/envs/rna_snakemake/lib/python3.12/site-packages/snakemake/executors/local.py", line 423, in run_wrapper
    run(
  File "/home/lucianhu/rna_snakemake/test_ting/Snakefile", line 1403, in __rule_infer_experiment
  File "/home/lucianhu/micromamba/envs/rna_snakemake/lib/python3.12/site-packages/snakemake/shell.py", line 357, in __new__
    raise sp.CalledProcessError(retcode, cmd)
subprocess.CalledProcessError: Command 'set -euo pipefail;  
        infer_experiment.py -i results/align/bam_markup/RAP1_REP1_treatment/RAP1_REP1_treatment.markdup.sorted.bam -r resources/annotation.filtered.bed > results/infer_experiment/RAP1_REP1_treatment/RAP1_REP1_treatment.infer_experiment.txt 2>' returned non-zero exit status 2.

During handling of the above exception, another exception occurred:

Traceback (most recent call last):
  File "/home/lucianhu/micromamba/envs/rna_snakemake/lib/python3.12/site-packages/snakemake/executors/local.py", line 261, in _callback
    raise ex
  File "/home/lucianhu/micromamba/envs/rna_snakemake/lib/python3.12/concurrent/futures/thread.py", line 58, in run
    result = self.fn(*self.args, **self.kwargs)
             ^^^^^^^^^^^^^^^^^^^^^^^^^^^^^^^^^^
  File "/home/lucianhu/micromamba/envs/rna_snakemake/lib/python3.12/site-packages/snakemake/executors/local.py", line 247, in cached_or_run
    run_func(*args)
  File "/home/lucianhu/micromamba/envs/rna_snakemake/lib/python3.12/site-packages/snakemake/executors/local.py", line 459, in run_wrapper
    raise RuleException(
snakemake.exceptions.RuleException: CalledProcessError in file /home/lucianhu/rna_snakemake/test_ting/Snakefile, line 680:
Command 'set -euo pipefail;  
        infer_experiment.py -i results/align/bam_markup/RAP1_REP1_treatment/RAP1_REP1_treatment.markdup.sorted.bam -r resources/annotation.filtered.bed > results/infer_experiment/RAP1_REP1_treatment/RAP1_REP1_treatment.infer_experiment.txt 2>' returned non-zero exit status 2.

[Mon Aug 19 00:40:31 2024]
Job 73: WT_REP2_control: Running Infer experiment
Reason: Missing output files: results/infer_experiment/WT_REP2_control/WT_REP2_control.infer_experiment.txt
Full Traceback (most recent call last):
  File "/home/lucianhu/micromamba/envs/rna_snakemake/lib/python3.12/site-packages/snakemake/executors/local.py", line 423, in run_wrapper
    run(
  File "/home/lucianhu/rna_snakemake/test_ting/Snakefile", line 1403, in __rule_infer_experiment
  File "/home/lucianhu/micromamba/envs/rna_snakemake/lib/python3.12/site-packages/snakemake/shell.py", line 357, in __new__
    raise sp.CalledProcessError(retcode, cmd)
subprocess.CalledProcessError: Command 'set -euo pipefail;  
        infer_experiment.py -i results/align/bam_markup/RAP1_REP3_treatment/RAP1_REP3_treatment.markdup.sorted.bam -r resources/annotation.filtered.bed > results/infer_experiment/RAP1_REP3_treatment/RAP1_REP3_treatment.infer_experiment.txt 2>' returned non-zero exit status 2.

During handling of the above exception, another exception occurred:

Traceback (most recent call last):
  File "/home/lucianhu/micromamba/envs/rna_snakemake/lib/python3.12/site-packages/snakemake/executors/local.py", line 261, in _callback
    raise ex
  File "/home/lucianhu/micromamba/envs/rna_snakemake/lib/python3.12/concurrent/futures/thread.py", line 58, in run
    result = self.fn(*self.args, **self.kwargs)
             ^^^^^^^^^^^^^^^^^^^^^^^^^^^^^^^^^^
  File "/home/lucianhu/micromamba/envs/rna_snakemake/lib/python3.12/site-packages/snakemake/executors/local.py", line 247, in cached_or_run
    run_func(*args)
  File "/home/lucianhu/micromamba/envs/rna_snakemake/lib/python3.12/site-packages/snakemake/executors/local.py", line 459, in run_wrapper
    raise RuleException(
snakemake.exceptions.RuleException: CalledProcessError in file /home/lucianhu/rna_snakemake/test_ting/Snakefile, line 680:
Command 'set -euo pipefail;  
        infer_experiment.py -i results/align/bam_markup/RAP1_REP3_treatment/RAP1_REP3_treatment.markdup.sorted.bam -r resources/annotation.filtered.bed > results/infer_experiment/RAP1_REP3_treatment/RAP1_REP3_treatment.infer_experiment.txt 2>' returned non-zero exit status 2.


Full Traceback (most recent call last):
  File "/home/lucianhu/micromamba/envs/rna_snakemake/lib/python3.12/site-packages/snakemake/executors/local.py", line 423, in run_wrapper
    run(
  File "/home/lucianhu/rna_snakemake/test_ting/Snakefile", line 1403, in __rule_infer_experiment
  File "/home/lucianhu/micromamba/envs/rna_snakemake/lib/python3.12/site-packages/snakemake/shell.py", line 357, in __new__
    raise sp.CalledProcessError(retcode, cmd)
subprocess.CalledProcessError: Command 'set -euo pipefail;  
        infer_experiment.py -i results/align/bam_markup/RAP1_REP2_treatment/RAP1_REP2_treatment.markdup.sorted.bam -r resources/annotation.filtered.bed > results/infer_experiment/RAP1_REP2_treatment/RAP1_REP2_treatment.infer_experiment.txt 2>' returned non-zero exit status 2.

RuleException:
CalledProcessError in file /home/lucianhu/rna_snakemake/test_ting/Snakefile, line 680:
Command 'set -euo pipefail;  
        infer_experiment.py -i results/align/bam_markup/RAP1_REP1_treatment/RAP1_REP1_treatment.markdup.sorted.bam -r resources/annotation.filtered.bed > results/infer_experiment/RAP1_REP1_treatment/RAP1_REP1_treatment.infer_experiment.txt 2>' returned non-zero exit status 2.
Full Traceback (most recent call last):
  File "/home/lucianhu/micromamba/envs/rna_snakemake/lib/python3.12/site-packages/snakemake/executors/local.py", line 423, in run_wrapper
    run(
  File "/home/lucianhu/rna_snakemake/test_ting/Snakefile", line 1403, in __rule_infer_experiment
  File "/home/lucianhu/micromamba/envs/rna_snakemake/lib/python3.12/site-packages/snakemake/shell.py", line 357, in __new__
    raise sp.CalledProcessError(retcode, cmd)
subprocess.CalledProcessError: Command 'set -euo pipefail;  
        infer_experiment.py -i results/align/bam_markup/RAP1_REP2_treatment/RAP1_REP2_treatment.markdup.sorted.bam -r resources/annotation.filtered.bed > results/infer_experiment/RAP1_REP2_treatment/RAP1_REP2_treatment.infer_experiment.txt 2>' returned non-zero exit status 2.

During handling of the above exception, another exception occurred:

Traceback (most recent call last):
  File "/home/lucianhu/micromamba/envs/rna_snakemake/lib/python3.12/site-packages/snakemake/executors/local.py", line 261, in _callback
    raise ex
  File "/home/lucianhu/micromamba/envs/rna_snakemake/lib/python3.12/concurrent/futures/thread.py", line 58, in run
    result = self.fn(*self.args, **self.kwargs)
             ^^^^^^^^^^^^^^^^^^^^^^^^^^^^^^^^^^
  File "/home/lucianhu/micromamba/envs/rna_snakemake/lib/python3.12/site-packages/snakemake/executors/local.py", line 247, in cached_or_run
    run_func(*args)
  File "/home/lucianhu/micromamba/envs/rna_snakemake/lib/python3.12/site-packages/snakemake/executors/local.py", line 459, in run_wrapper
    raise RuleException(
snakemake.exceptions.RuleException: CalledProcessError in file /home/lucianhu/rna_snakemake/test_ting/Snakefile, line 680:
Command 'set -euo pipefail;  
        infer_experiment.py -i results/align/bam_markup/RAP1_REP2_treatment/RAP1_REP2_treatment.markdup.sorted.bam -r resources/annotation.filtered.bed > results/infer_experiment/RAP1_REP2_treatment/RAP1_REP2_treatment.infer_experiment.txt 2>' returned non-zero exit status 2.

[Mon Aug 19 00:40:31 2024]
Error in rule infer_experiment:
    jobid: 75
    input: results/align/bam_markup/RAP1_REP1_treatment/RAP1_REP1_treatment.markdup.sorted.bam, resources/annotation.filtered.bed
    output: results/infer_experiment/RAP1_REP1_treatment/RAP1_REP1_treatment.infer_experiment.txt
    conda-env: /home/lucianhu/rna_snakemake/test_ting/.snakemake/conda/75573665ecd5eadd18c4d5be2650a852_
    shell:
        
        infer_experiment.py -i results/align/bam_markup/RAP1_REP1_treatment/RAP1_REP1_treatment.markdup.sorted.bam -r resources/annotation.filtered.bed > results/infer_experiment/RAP1_REP1_treatment/RAP1_REP1_treatment.infer_experiment.txt 2> 
        
        (one of the commands exited with non-zero exit code; note that snakemake uses bash strict mode!)


RuleException:
CalledProcessError in file /home/lucianhu/rna_snakemake/test_ting/Snakefile, line 680:
Command 'set -euo pipefail;  
        infer_experiment.py -i results/align/bam_markup/RAP1_REP3_treatment/RAP1_REP3_treatment.markdup.sorted.bam -r resources/annotation.filtered.bed > results/infer_experiment/RAP1_REP3_treatment/RAP1_REP3_treatment.infer_experiment.txt 2>' returned non-zero exit status 2.
[Mon Aug 19 00:40:31 2024]
Job 71: WT_REP1_control: Running Infer experiment
Reason: Missing output files: results/infer_experiment/WT_REP1_control/WT_REP1_control.infer_experiment.txt

[Mon Aug 19 00:40:31 2024]
Error in rule infer_experiment:
    jobid: 77
    input: results/align/bam_markup/RAP1_REP3_treatment/RAP1_REP3_treatment.markdup.sorted.bam, resources/annotation.filtered.bed
    output: results/infer_experiment/RAP1_REP3_treatment/RAP1_REP3_treatment.infer_experiment.txt
    conda-env: /home/lucianhu/rna_snakemake/test_ting/.snakemake/conda/75573665ecd5eadd18c4d5be2650a852_
    shell:
        
        infer_experiment.py -i results/align/bam_markup/RAP1_REP3_treatment/RAP1_REP3_treatment.markdup.sorted.bam -r resources/annotation.filtered.bed > results/infer_experiment/RAP1_REP3_treatment/RAP1_REP3_treatment.infer_experiment.txt 2> 
        
        (one of the commands exited with non-zero exit code; note that snakemake uses bash strict mode!)

Full Traceback (most recent call last):
  File "/home/lucianhu/micromamba/envs/rna_snakemake/lib/python3.12/site-packages/snakemake/executors/local.py", line 423, in run_wrapper
    run(
  File "/home/lucianhu/rna_snakemake/test_ting/Snakefile", line 1403, in __rule_infer_experiment
  File "/home/lucianhu/micromamba/envs/rna_snakemake/lib/python3.12/site-packages/snakemake/shell.py", line 357, in __new__
    raise sp.CalledProcessError(retcode, cmd)
subprocess.CalledProcessError: Command 'set -euo pipefail;  
        infer_experiment.py -i results/align/bam_markup/WT_REP2_control/WT_REP2_control.markdup.sorted.bam -r resources/annotation.filtered.bed > results/infer_experiment/WT_REP2_control/WT_REP2_control.infer_experiment.txt 2>' returned non-zero exit status 2.

RuleException:
CalledProcessError in file /home/lucianhu/rna_snakemake/test_ting/Snakefile, line 680:
Command 'set -euo pipefail;  
        infer_experiment.py -i results/align/bam_markup/RAP1_REP2_treatment/RAP1_REP2_treatment.markdup.sorted.bam -r resources/annotation.filtered.bed > results/infer_experiment/RAP1_REP2_treatment/RAP1_REP2_treatment.infer_experiment.txt 2>' returned non-zero exit status 2.
[Mon Aug 19 00:40:31 2024]

Error in rule infer_experiment:
    jobid: 76
    input: results/align/bam_markup/RAP1_REP2_treatment/RAP1_REP2_treatment.markdup.sorted.bam, resources/annotation.filtered.bed
    output: results/infer_experiment/RAP1_REP2_treatment/RAP1_REP2_treatment.infer_experiment.txt
    conda-env: /home/lucianhu/rna_snakemake/test_ting/.snakemake/conda/75573665ecd5eadd18c4d5be2650a852_
    shell:
        
        infer_experiment.py -i results/align/bam_markup/RAP1_REP2_treatment/RAP1_REP2_treatment.markdup.sorted.bam -r resources/annotation.filtered.bed > results/infer_experiment/RAP1_REP2_treatment/RAP1_REP2_treatment.infer_experiment.txt 2> 
        
        (one of the commands exited with non-zero exit code; note that snakemake uses bash strict mode!)

Full Traceback (most recent call last):
  File "/home/lucianhu/micromamba/envs/rna_snakemake/lib/python3.12/site-packages/snakemake/executors/local.py", line 423, in run_wrapper
    run(
  File "/home/lucianhu/rna_snakemake/test_ting/Snakefile", line 1403, in __rule_infer_experiment
  File "/home/lucianhu/micromamba/envs/rna_snakemake/lib/python3.12/site-packages/snakemake/shell.py", line 357, in __new__
    raise sp.CalledProcessError(retcode, cmd)
subprocess.CalledProcessError: Command 'set -euo pipefail;  
        infer_experiment.py -i results/align/bam_markup/WT_REP2_control/WT_REP2_control.markdup.sorted.bam -r resources/annotation.filtered.bed > results/infer_experiment/WT_REP2_control/WT_REP2_control.infer_experiment.txt 2>' returned non-zero exit status 2.

During handling of the above exception, another exception occurred:

Traceback (most recent call last):
  File "/home/lucianhu/micromamba/envs/rna_snakemake/lib/python3.12/site-packages/snakemake/executors/local.py", line 261, in _callback
    raise ex
  File "/home/lucianhu/micromamba/envs/rna_snakemake/lib/python3.12/concurrent/futures/thread.py", line 58, in run
    result = self.fn(*self.args, **self.kwargs)
             ^^^^^^^^^^^^^^^^^^^^^^^^^^^^^^^^^^
  File "/home/lucianhu/micromamba/envs/rna_snakemake/lib/python3.12/site-packages/snakemake/executors/local.py", line 247, in cached_or_run
    run_func(*args)
  File "/home/lucianhu/micromamba/envs/rna_snakemake/lib/python3.12/site-packages/snakemake/executors/local.py", line 459, in run_wrapper
    raise RuleException(
snakemake.exceptions.RuleException: CalledProcessError in file /home/lucianhu/rna_snakemake/test_ting/Snakefile, line 680:
Command 'set -euo pipefail;  
        infer_experiment.py -i results/align/bam_markup/WT_REP2_control/WT_REP2_control.markdup.sorted.bam -r resources/annotation.filtered.bed > results/infer_experiment/WT_REP2_control/WT_REP2_control.infer_experiment.txt 2>' returned non-zero exit status 2.

[Mon Aug 19 00:40:31 2024]
Full Traceback (most recent call last):
  File "/home/lucianhu/micromamba/envs/rna_snakemake/lib/python3.12/site-packages/snakemake/executors/local.py", line 423, in run_wrapper
    run(
  File "/home/lucianhu/rna_snakemake/test_ting/Snakefile", line 1403, in __rule_infer_experiment
  File "/home/lucianhu/micromamba/envs/rna_snakemake/lib/python3.12/site-packages/snakemake/shell.py", line 357, in __new__
    raise sp.CalledProcessError(retcode, cmd)
subprocess.CalledProcessError: Command 'set -euo pipefail;  
        infer_experiment.py -i results/align/bam_markup/WT_REP1_control/WT_REP1_control.markdup.sorted.bam -r resources/annotation.filtered.bed > results/infer_experiment/WT_REP1_control/WT_REP1_control.infer_experiment.txt 2>' returned non-zero exit status 2.

Job 74: WT_REP3_control: Running Infer experiment
Full Traceback (most recent call last):
  File "/home/lucianhu/micromamba/envs/rna_snakemake/lib/python3.12/site-packages/snakemake/executors/local.py", line 423, in run_wrapper
    run(
  File "/home/lucianhu/rna_snakemake/test_ting/Snakefile", line 1403, in __rule_infer_experiment
  File "/home/lucianhu/micromamba/envs/rna_snakemake/lib/python3.12/site-packages/snakemake/shell.py", line 357, in __new__
    raise sp.CalledProcessError(retcode, cmd)
subprocess.CalledProcessError: Command 'set -euo pipefail;  
        infer_experiment.py -i results/align/bam_markup/WT_REP1_control/WT_REP1_control.markdup.sorted.bam -r resources/annotation.filtered.bed > results/infer_experiment/WT_REP1_control/WT_REP1_control.infer_experiment.txt 2>' returned non-zero exit status 2.

During handling of the above exception, another exception occurred:

Traceback (most recent call last):
  File "/home/lucianhu/micromamba/envs/rna_snakemake/lib/python3.12/site-packages/snakemake/executors/local.py", line 261, in _callback
    raise ex
  File "/home/lucianhu/micromamba/envs/rna_snakemake/lib/python3.12/concurrent/futures/thread.py", line 58, in run
    result = self.fn(*self.args, **self.kwargs)
             ^^^^^^^^^^^^^^^^^^^^^^^^^^^^^^^^^^
  File "/home/lucianhu/micromamba/envs/rna_snakemake/lib/python3.12/site-packages/snakemake/executors/local.py", line 247, in cached_or_run
    run_func(*args)
  File "/home/lucianhu/micromamba/envs/rna_snakemake/lib/python3.12/site-packages/snakemake/executors/local.py", line 459, in run_wrapper
    raise RuleException(
snakemake.exceptions.RuleException: CalledProcessError in file /home/lucianhu/rna_snakemake/test_ting/Snakefile, line 680:
Command 'set -euo pipefail;  
        infer_experiment.py -i results/align/bam_markup/WT_REP1_control/WT_REP1_control.markdup.sorted.bam -r resources/annotation.filtered.bed > results/infer_experiment/WT_REP1_control/WT_REP1_control.infer_experiment.txt 2>' returned non-zero exit status 2.

Reason: Missing output files: results/infer_experiment/WT_REP3_control/WT_REP3_control.infer_experiment.txt

RuleException:
CalledProcessError in file /home/lucianhu/rna_snakemake/test_ting/Snakefile, line 680:
Command 'set -euo pipefail;  
        infer_experiment.py -i results/align/bam_markup/WT_REP2_control/WT_REP2_control.markdup.sorted.bam -r resources/annotation.filtered.bed > results/infer_experiment/WT_REP2_control/WT_REP2_control.infer_experiment.txt 2>' returned non-zero exit status 2.
[Mon Aug 19 00:40:31 2024]
Error in rule infer_experiment:
    jobid: 73
    input: results/align/bam_markup/WT_REP2_control/WT_REP2_control.markdup.sorted.bam, resources/annotation.filtered.bed
    output: results/infer_experiment/WT_REP2_control/WT_REP2_control.infer_experiment.txt
    conda-env: /home/lucianhu/rna_snakemake/test_ting/.snakemake/conda/75573665ecd5eadd18c4d5be2650a852_
    shell:
        
        infer_experiment.py -i results/align/bam_markup/WT_REP2_control/WT_REP2_control.markdup.sorted.bam -r resources/annotation.filtered.bed > results/infer_experiment/WT_REP2_control/WT_REP2_control.infer_experiment.txt 2> 
        
        (one of the commands exited with non-zero exit code; note that snakemake uses bash strict mode!)

RuleException:
CalledProcessError in file /home/lucianhu/rna_snakemake/test_ting/Snakefile, line 680:
Command 'set -euo pipefail;  
        infer_experiment.py -i results/align/bam_markup/WT_REP1_control/WT_REP1_control.markdup.sorted.bam -r resources/annotation.filtered.bed > results/infer_experiment/WT_REP1_control/WT_REP1_control.infer_experiment.txt 2>' returned non-zero exit status 2.
[Mon Aug 19 00:40:31 2024]
Full Traceback (most recent call last):
  File "/home/lucianhu/micromamba/envs/rna_snakemake/lib/python3.12/site-packages/snakemake/executors/local.py", line 423, in run_wrapper
    run(
  File "/home/lucianhu/rna_snakemake/test_ting/Snakefile", line 1403, in __rule_infer_experiment
  File "/home/lucianhu/micromamba/envs/rna_snakemake/lib/python3.12/site-packages/snakemake/shell.py", line 357, in __new__
    raise sp.CalledProcessError(retcode, cmd)
subprocess.CalledProcessError: Command 'set -euo pipefail;  
        infer_experiment.py -i results/align/bam_markup/WT_REP3_control/WT_REP3_control.markdup.sorted.bam -r resources/annotation.filtered.bed > results/infer_experiment/WT_REP3_control/WT_REP3_control.infer_experiment.txt 2>' returned non-zero exit status 2.

Error in rule infer_experiment:
    jobid: 71
    input: results/align/bam_markup/WT_REP1_control/WT_REP1_control.markdup.sorted.bam, resources/annotation.filtered.bed
    output: results/infer_experiment/WT_REP1_control/WT_REP1_control.infer_experiment.txt
    conda-env: /home/lucianhu/rna_snakemake/test_ting/.snakemake/conda/75573665ecd5eadd18c4d5be2650a852_
    shell:
        
        infer_experiment.py -i results/align/bam_markup/WT_REP1_control/WT_REP1_control.markdup.sorted.bam -r resources/annotation.filtered.bed > results/infer_experiment/WT_REP1_control/WT_REP1_control.infer_experiment.txt 2> 
        
        (one of the commands exited with non-zero exit code; note that snakemake uses bash strict mode!)

Full Traceback (most recent call last):
  File "/home/lucianhu/micromamba/envs/rna_snakemake/lib/python3.12/site-packages/snakemake/executors/local.py", line 423, in run_wrapper
    run(
  File "/home/lucianhu/rna_snakemake/test_ting/Snakefile", line 1403, in __rule_infer_experiment
  File "/home/lucianhu/micromamba/envs/rna_snakemake/lib/python3.12/site-packages/snakemake/shell.py", line 357, in __new__
    raise sp.CalledProcessError(retcode, cmd)
subprocess.CalledProcessError: Command 'set -euo pipefail;  
        infer_experiment.py -i results/align/bam_markup/WT_REP3_control/WT_REP3_control.markdup.sorted.bam -r resources/annotation.filtered.bed > results/infer_experiment/WT_REP3_control/WT_REP3_control.infer_experiment.txt 2>' returned non-zero exit status 2.

During handling of the above exception, another exception occurred:

Traceback (most recent call last):
  File "/home/lucianhu/micromamba/envs/rna_snakemake/lib/python3.12/site-packages/snakemake/executors/local.py", line 261, in _callback
    raise ex
  File "/home/lucianhu/micromamba/envs/rna_snakemake/lib/python3.12/concurrent/futures/thread.py", line 58, in run
    result = self.fn(*self.args, **self.kwargs)
             ^^^^^^^^^^^^^^^^^^^^^^^^^^^^^^^^^^
  File "/home/lucianhu/micromamba/envs/rna_snakemake/lib/python3.12/site-packages/snakemake/executors/local.py", line 247, in cached_or_run
    run_func(*args)
  File "/home/lucianhu/micromamba/envs/rna_snakemake/lib/python3.12/site-packages/snakemake/executors/local.py", line 459, in run_wrapper
    raise RuleException(
snakemake.exceptions.RuleException: CalledProcessError in file /home/lucianhu/rna_snakemake/test_ting/Snakefile, line 680:
Command 'set -euo pipefail;  
        infer_experiment.py -i results/align/bam_markup/WT_REP3_control/WT_REP3_control.markdup.sorted.bam -r resources/annotation.filtered.bed > results/infer_experiment/WT_REP3_control/WT_REP3_control.infer_experiment.txt 2>' returned non-zero exit status 2.

RuleException:
CalledProcessError in file /home/lucianhu/rna_snakemake/test_ting/Snakefile, line 680:
Command 'set -euo pipefail;  
        infer_experiment.py -i results/align/bam_markup/WT_REP3_control/WT_REP3_control.markdup.sorted.bam -r resources/annotation.filtered.bed > results/infer_experiment/WT_REP3_control/WT_REP3_control.infer_experiment.txt 2>' returned non-zero exit status 2.
[Mon Aug 19 00:40:31 2024]
Error in rule infer_experiment:
    jobid: 74
    input: results/align/bam_markup/WT_REP3_control/WT_REP3_control.markdup.sorted.bam, resources/annotation.filtered.bed
    output: results/infer_experiment/WT_REP3_control/WT_REP3_control.infer_experiment.txt
    conda-env: /home/lucianhu/rna_snakemake/test_ting/.snakemake/conda/75573665ecd5eadd18c4d5be2650a852_
    shell:
        
        infer_experiment.py -i results/align/bam_markup/WT_REP3_control/WT_REP3_control.markdup.sorted.bam -r resources/annotation.filtered.bed > results/infer_experiment/WT_REP3_control/WT_REP3_control.infer_experiment.txt 2> 
        
        (one of the commands exited with non-zero exit code; note that snakemake uses bash strict mode!)

Shutting down, this might take some time.
Exiting because a job execution failed. Look above for error message
Complete log: .snakemake/log/2024-08-19T004031.001671.snakemake.log
unlocking
removing lock
removing lock
removed all locks
Full Traceback (most recent call last):
  File "/home/lucianhu/micromamba/envs/rna_snakemake/lib/python3.12/site-packages/snakemake/cli.py", line 2103, in args_to_api
    dag_api.execute_workflow(
  File "/home/lucianhu/micromamba/envs/rna_snakemake/lib/python3.12/site-packages/snakemake/api.py", line 594, in execute_workflow
    workflow.execute(
  File "/home/lucianhu/micromamba/envs/rna_snakemake/lib/python3.12/site-packages/snakemake/workflow.py", line 1286, in execute
    raise WorkflowError("At least one job did not complete successfully.")
snakemake_interface_common.exceptions.WorkflowError: At least one job did not complete successfully.

WorkflowError:
At least one job did not complete successfully.
