Building DAG of jobs...
shared_storage_local_copies: True
remote_exec: False
Using shell: /usr/bin/bash
Provided cores: 24
Rules claiming more threads will be scaled down.
Conda environments: ignored
Job stats:
job       count
------  -------
all           1
fastqc        6
total         7

Resources before job selection: {'_cores': 24, '_nodes': 9223372036854775807}
Ready jobs (6)
Select jobs to execute...
Selected jobs (4)
Resources after job selection: {'_cores': 0, '_nodes': 9223372036854775803}
Execute 4 jobs...

[Sun Aug 18 22:42:06 2024]
Job 3: WT_REP3_control: Performing quality control on raw reads
Reason: Missing output files: results/fastqc/WT_REP3_control; Code has changed since last execution; Software environment definition has changed since last execution


[Sun Aug 18 22:42:06 2024]
Job 1: WT_REP1_control: Performing quality control on raw reads
Reason: Missing output files: results/fastqc/WT_REP1_control; Code has changed since last execution; Software environment definition has changed since last execution


[Sun Aug 18 22:42:06 2024]
Job 4: RAP1_REP1_treatment: Performing quality control on raw reads
Reason: Missing output files: results/fastqc/RAP1_REP1_treatment; Code has changed since last execution; Software environment definition has changed since last execution


[Sun Aug 18 22:42:06 2024]
Job 2: WT_REP2_control: Performing quality control on raw reads
Reason: Missing output files: results/fastqc/WT_REP2_control; Code has changed since last execution; Software environment definition has changed since last execution

Full Traceback (most recent call last):
  File "/home/lucianhu/micromamba/envs/rna_snakemake/lib/python3.12/site-packages/snakemake/executors/local.py", line 423, in run_wrapper
    run(
  File "/home/lucianhu/rna_snakemake/test_ting/Snakefile", line 435, in __rule_fastqc
    fasta="resources/genome.fa"
  File "/home/lucianhu/micromamba/envs/rna_snakemake/lib/python3.12/site-packages/snakemake/shell.py", line 357, in __new__
    raise sp.CalledProcessError(retcode, cmd)
subprocess.CalledProcessError: Command 'set -euo pipefail;  
        fastqc --quiet --threads 6 /home/lucianhu/rna_snakemake/rna_snakemake/test-datasets/testdata/SRR6357070_1.fastq.gz /home/lucianhu/rna_snakemake/rna_snakemake/test-datasets/testdata/SRR6357070_2.fastq.gz         --outdir results/fastqc/WT_REP1_control &> logs/fastqc/WT_REP1_control.fastqc.log' returned non-zero exit status 2.

Full Traceback (most recent call last):
  File "/home/lucianhu/micromamba/envs/rna_snakemake/lib/python3.12/site-packages/snakemake/executors/local.py", line 423, in run_wrapper
    run(
  File "/home/lucianhu/rna_snakemake/test_ting/Snakefile", line 435, in __rule_fastqc
    fasta="resources/genome.fa"
  File "/home/lucianhu/micromamba/envs/rna_snakemake/lib/python3.12/site-packages/snakemake/shell.py", line 357, in __new__
    raise sp.CalledProcessError(retcode, cmd)
subprocess.CalledProcessError: Command 'set -euo pipefail;  
        fastqc --quiet --threads 6 /home/lucianhu/rna_snakemake/rna_snakemake/test-datasets/testdata/SRR6357070_1.fastq.gz /home/lucianhu/rna_snakemake/rna_snakemake/test-datasets/testdata/SRR6357070_2.fastq.gz         --outdir results/fastqc/WT_REP1_control &> logs/fastqc/WT_REP1_control.fastqc.log' returned non-zero exit status 2.

During handling of the above exception, another exception occurred:

Traceback (most recent call last):
  File "/home/lucianhu/micromamba/envs/rna_snakemake/lib/python3.12/site-packages/snakemake/executors/local.py", line 261, in _callback
    raise ex
  File "/home/lucianhu/micromamba/envs/rna_snakemake/lib/python3.12/concurrent/futures/thread.py", line 58, in run
    result = self.fn(*self.args, **self.kwargs)
             ^^^^^^^^^^^^^^^^^^^^^^^^^^^^^^^^^^
  File "/home/lucianhu/micromamba/envs/rna_snakemake/lib/python3.12/site-packages/snakemake/executors/local.py", line 247, in cached_or_run
    run_func(*args)
  File "/home/lucianhu/micromamba/envs/rna_snakemake/lib/python3.12/site-packages/snakemake/executors/local.py", line 459, in run_wrapper
    raise RuleException(
snakemake.exceptions.RuleException: CalledProcessError in file /home/lucianhu/rna_snakemake/test_ting/Snakefile, line 237:
Command 'set -euo pipefail;  
        fastqc --quiet --threads 6 /home/lucianhu/rna_snakemake/rna_snakemake/test-datasets/testdata/SRR6357070_1.fastq.gz /home/lucianhu/rna_snakemake/rna_snakemake/test-datasets/testdata/SRR6357070_2.fastq.gz         --outdir results/fastqc/WT_REP1_control &> logs/fastqc/WT_REP1_control.fastqc.log' returned non-zero exit status 2.

RuleException:
CalledProcessError in file /home/lucianhu/rna_snakemake/test_ting/Snakefile, line 237:
Command 'set -euo pipefail;  
        fastqc --quiet --threads 6 /home/lucianhu/rna_snakemake/rna_snakemake/test-datasets/testdata/SRR6357070_1.fastq.gz /home/lucianhu/rna_snakemake/rna_snakemake/test-datasets/testdata/SRR6357070_2.fastq.gz         --outdir results/fastqc/WT_REP1_control &> logs/fastqc/WT_REP1_control.fastqc.log' returned non-zero exit status 2.
[Sun Aug 18 22:42:06 2024]
Error in rule fastqc:
    jobid: 1
    input: /home/lucianhu/rna_snakemake/rna_snakemake/test-datasets/testdata/SRR6357070_1.fastq.gz, /home/lucianhu/rna_snakemake/rna_snakemake/test-datasets/testdata/SRR6357070_2.fastq.gz
    output: results/fastqc/WT_REP1_control
    log: logs/fastqc/WT_REP1_control.fastqc.log (check log file(s) for error details)
    conda-env: /home/lucianhu/rna_snakemake/test_ting/.snakemake/conda/6560e655f15db8ccf0d5611fa7df93d1_
    shell:
        
        fastqc --quiet --threads 6 /home/lucianhu/rna_snakemake/rna_snakemake/test-datasets/testdata/SRR6357070_1.fastq.gz /home/lucianhu/rna_snakemake/rna_snakemake/test-datasets/testdata/SRR6357070_2.fastq.gz         --outdir results/fastqc/WT_REP1_control &> logs/fastqc/WT_REP1_control.fastqc.log
        
        (one of the commands exited with non-zero exit code; note that snakemake uses bash strict mode!)

Full Traceback (most recent call last):
  File "/home/lucianhu/micromamba/envs/rna_snakemake/lib/python3.12/site-packages/snakemake/executors/local.py", line 423, in run_wrapper
    run(
  File "/home/lucianhu/rna_snakemake/test_ting/Snakefile", line 435, in __rule_fastqc
    fasta="resources/genome.fa"
  File "/home/lucianhu/micromamba/envs/rna_snakemake/lib/python3.12/site-packages/snakemake/shell.py", line 357, in __new__
    raise sp.CalledProcessError(retcode, cmd)
subprocess.CalledProcessError: Command 'set -euo pipefail;  
        fastqc --quiet --threads 6 /home/lucianhu/rna_snakemake/rna_snakemake/test-datasets/testdata/SRR6357071_1.fastq.gz /home/lucianhu/rna_snakemake/rna_snakemake/test-datasets/testdata/SRR6357071_2.fastq.gz         --outdir results/fastqc/WT_REP2_control &> logs/fastqc/WT_REP2_control.fastqc.log' returned non-zero exit status 2.

Full Traceback (most recent call last):
  File "/home/lucianhu/micromamba/envs/rna_snakemake/lib/python3.12/site-packages/snakemake/executors/local.py", line 423, in run_wrapper
    run(
  File "/home/lucianhu/rna_snakemake/test_ting/Snakefile", line 435, in __rule_fastqc
    fasta="resources/genome.fa"
  File "/home/lucianhu/micromamba/envs/rna_snakemake/lib/python3.12/site-packages/snakemake/shell.py", line 357, in __new__
    raise sp.CalledProcessError(retcode, cmd)
subprocess.CalledProcessError: Command 'set -euo pipefail;  
        fastqc --quiet --threads 6 /home/lucianhu/rna_snakemake/rna_snakemake/test-datasets/testdata/SRR6357071_1.fastq.gz /home/lucianhu/rna_snakemake/rna_snakemake/test-datasets/testdata/SRR6357071_2.fastq.gz         --outdir results/fastqc/WT_REP2_control &> logs/fastqc/WT_REP2_control.fastqc.log' returned non-zero exit status 2.

During handling of the above exception, another exception occurred:

Traceback (most recent call last):
  File "/home/lucianhu/micromamba/envs/rna_snakemake/lib/python3.12/site-packages/snakemake/executors/local.py", line 261, in _callback
    raise ex
  File "/home/lucianhu/micromamba/envs/rna_snakemake/lib/python3.12/concurrent/futures/thread.py", line 58, in run
    result = self.fn(*self.args, **self.kwargs)
             ^^^^^^^^^^^^^^^^^^^^^^^^^^^^^^^^^^
  File "/home/lucianhu/micromamba/envs/rna_snakemake/lib/python3.12/site-packages/snakemake/executors/local.py", line 247, in cached_or_run
    run_func(*args)
  File "/home/lucianhu/micromamba/envs/rna_snakemake/lib/python3.12/site-packages/snakemake/executors/local.py", line 459, in run_wrapper
    raise RuleException(
snakemake.exceptions.RuleException: CalledProcessError in file /home/lucianhu/rna_snakemake/test_ting/Snakefile, line 237:
Command 'set -euo pipefail;  
        fastqc --quiet --threads 6 /home/lucianhu/rna_snakemake/rna_snakemake/test-datasets/testdata/SRR6357071_1.fastq.gz /home/lucianhu/rna_snakemake/rna_snakemake/test-datasets/testdata/SRR6357071_2.fastq.gz         --outdir results/fastqc/WT_REP2_control &> logs/fastqc/WT_REP2_control.fastqc.log' returned non-zero exit status 2.

RuleException:
CalledProcessError in file /home/lucianhu/rna_snakemake/test_ting/Snakefile, line 237:
Command 'set -euo pipefail;  
        fastqc --quiet --threads 6 /home/lucianhu/rna_snakemake/rna_snakemake/test-datasets/testdata/SRR6357071_1.fastq.gz /home/lucianhu/rna_snakemake/rna_snakemake/test-datasets/testdata/SRR6357071_2.fastq.gz         --outdir results/fastqc/WT_REP2_control &> logs/fastqc/WT_REP2_control.fastqc.log' returned non-zero exit status 2.
[Sun Aug 18 22:42:06 2024]
Error in rule fastqc:
    jobid: 2
    input: /home/lucianhu/rna_snakemake/rna_snakemake/test-datasets/testdata/SRR6357071_1.fastq.gz, /home/lucianhu/rna_snakemake/rna_snakemake/test-datasets/testdata/SRR6357071_2.fastq.gz
    output: results/fastqc/WT_REP2_control
    log: logs/fastqc/WT_REP2_control.fastqc.log (check log file(s) for error details)
    conda-env: /home/lucianhu/rna_snakemake/test_ting/.snakemake/conda/6560e655f15db8ccf0d5611fa7df93d1_
    shell:
        
        fastqc --quiet --threads 6 /home/lucianhu/rna_snakemake/rna_snakemake/test-datasets/testdata/SRR6357071_1.fastq.gz /home/lucianhu/rna_snakemake/rna_snakemake/test-datasets/testdata/SRR6357071_2.fastq.gz         --outdir results/fastqc/WT_REP2_control &> logs/fastqc/WT_REP2_control.fastqc.log
        
        (one of the commands exited with non-zero exit code; note that snakemake uses bash strict mode!)

Full Traceback (most recent call last):
  File "/home/lucianhu/micromamba/envs/rna_snakemake/lib/python3.12/site-packages/snakemake/executors/local.py", line 423, in run_wrapper
    run(
  File "/home/lucianhu/rna_snakemake/test_ting/Snakefile", line 435, in __rule_fastqc
    fasta="resources/genome.fa"
  File "/home/lucianhu/micromamba/envs/rna_snakemake/lib/python3.12/site-packages/snakemake/shell.py", line 357, in __new__
    raise sp.CalledProcessError(retcode, cmd)
subprocess.CalledProcessError: Command 'set -euo pipefail;  
        fastqc --quiet --threads 6 /home/lucianhu/rna_snakemake/rna_snakemake/test-datasets/testdata/SRR6357072_1.fastq.gz /home/lucianhu/rna_snakemake/rna_snakemake/test-datasets/testdata/SRR6357072_2.fastq.gz         --outdir results/fastqc/WT_REP3_control &> logs/fastqc/WT_REP3_control.fastqc.log' returned non-zero exit status 2.

Full Traceback (most recent call last):
  File "/home/lucianhu/micromamba/envs/rna_snakemake/lib/python3.12/site-packages/snakemake/executors/local.py", line 423, in run_wrapper
    run(
  File "/home/lucianhu/rna_snakemake/test_ting/Snakefile", line 435, in __rule_fastqc
    fasta="resources/genome.fa"
  File "/home/lucianhu/micromamba/envs/rna_snakemake/lib/python3.12/site-packages/snakemake/shell.py", line 357, in __new__
    raise sp.CalledProcessError(retcode, cmd)
subprocess.CalledProcessError: Command 'set -euo pipefail;  
        fastqc --quiet --threads 6 /home/lucianhu/rna_snakemake/rna_snakemake/test-datasets/testdata/SRR6357072_1.fastq.gz /home/lucianhu/rna_snakemake/rna_snakemake/test-datasets/testdata/SRR6357072_2.fastq.gz         --outdir results/fastqc/WT_REP3_control &> logs/fastqc/WT_REP3_control.fastqc.log' returned non-zero exit status 2.

During handling of the above exception, another exception occurred:

Traceback (most recent call last):
  File "/home/lucianhu/micromamba/envs/rna_snakemake/lib/python3.12/site-packages/snakemake/executors/local.py", line 261, in _callback
    raise ex
  File "/home/lucianhu/micromamba/envs/rna_snakemake/lib/python3.12/concurrent/futures/thread.py", line 58, in run
    result = self.fn(*self.args, **self.kwargs)
             ^^^^^^^^^^^^^^^^^^^^^^^^^^^^^^^^^^
  File "/home/lucianhu/micromamba/envs/rna_snakemake/lib/python3.12/site-packages/snakemake/executors/local.py", line 247, in cached_or_run
    run_func(*args)
  File "/home/lucianhu/micromamba/envs/rna_snakemake/lib/python3.12/site-packages/snakemake/executors/local.py", line 459, in run_wrapper
    raise RuleException(
snakemake.exceptions.RuleException: CalledProcessError in file /home/lucianhu/rna_snakemake/test_ting/Snakefile, line 237:
Command 'set -euo pipefail;  
        fastqc --quiet --threads 6 /home/lucianhu/rna_snakemake/rna_snakemake/test-datasets/testdata/SRR6357072_1.fastq.gz /home/lucianhu/rna_snakemake/rna_snakemake/test-datasets/testdata/SRR6357072_2.fastq.gz         --outdir results/fastqc/WT_REP3_control &> logs/fastqc/WT_REP3_control.fastqc.log' returned non-zero exit status 2.

RuleException:
CalledProcessError in file /home/lucianhu/rna_snakemake/test_ting/Snakefile, line 237:
Command 'set -euo pipefail;  
        fastqc --quiet --threads 6 /home/lucianhu/rna_snakemake/rna_snakemake/test-datasets/testdata/SRR6357072_1.fastq.gz /home/lucianhu/rna_snakemake/rna_snakemake/test-datasets/testdata/SRR6357072_2.fastq.gz         --outdir results/fastqc/WT_REP3_control &> logs/fastqc/WT_REP3_control.fastqc.log' returned non-zero exit status 2.
[Sun Aug 18 22:42:06 2024]
Error in rule fastqc:
    jobid: 3
    input: /home/lucianhu/rna_snakemake/rna_snakemake/test-datasets/testdata/SRR6357072_1.fastq.gz, /home/lucianhu/rna_snakemake/rna_snakemake/test-datasets/testdata/SRR6357072_2.fastq.gz
    output: results/fastqc/WT_REP3_control
    log: logs/fastqc/WT_REP3_control.fastqc.log (check log file(s) for error details)
    conda-env: /home/lucianhu/rna_snakemake/test_ting/.snakemake/conda/6560e655f15db8ccf0d5611fa7df93d1_
    shell:
        
        fastqc --quiet --threads 6 /home/lucianhu/rna_snakemake/rna_snakemake/test-datasets/testdata/SRR6357072_1.fastq.gz /home/lucianhu/rna_snakemake/rna_snakemake/test-datasets/testdata/SRR6357072_2.fastq.gz         --outdir results/fastqc/WT_REP3_control &> logs/fastqc/WT_REP3_control.fastqc.log
        
        (one of the commands exited with non-zero exit code; note that snakemake uses bash strict mode!)

Full Traceback (most recent call last):
  File "/home/lucianhu/micromamba/envs/rna_snakemake/lib/python3.12/site-packages/snakemake/executors/local.py", line 423, in run_wrapper
    run(
  File "/home/lucianhu/rna_snakemake/test_ting/Snakefile", line 435, in __rule_fastqc
    fasta="resources/genome.fa"
  File "/home/lucianhu/micromamba/envs/rna_snakemake/lib/python3.12/site-packages/snakemake/shell.py", line 357, in __new__
    raise sp.CalledProcessError(retcode, cmd)
subprocess.CalledProcessError: Command 'set -euo pipefail;  
        fastqc --quiet --threads 6 /home/lucianhu/rna_snakemake/rna_snakemake/test-datasets/testdata/SRR6357073_1.fastq.gz          --outdir results/fastqc/RAP1_REP1_treatment &> logs/fastqc/RAP1_REP1_treatment.fastqc.log' returned non-zero exit status 2.

Full Traceback (most recent call last):
  File "/home/lucianhu/micromamba/envs/rna_snakemake/lib/python3.12/site-packages/snakemake/executors/local.py", line 423, in run_wrapper
    run(
  File "/home/lucianhu/rna_snakemake/test_ting/Snakefile", line 435, in __rule_fastqc
    fasta="resources/genome.fa"
  File "/home/lucianhu/micromamba/envs/rna_snakemake/lib/python3.12/site-packages/snakemake/shell.py", line 357, in __new__
    raise sp.CalledProcessError(retcode, cmd)
subprocess.CalledProcessError: Command 'set -euo pipefail;  
        fastqc --quiet --threads 6 /home/lucianhu/rna_snakemake/rna_snakemake/test-datasets/testdata/SRR6357073_1.fastq.gz          --outdir results/fastqc/RAP1_REP1_treatment &> logs/fastqc/RAP1_REP1_treatment.fastqc.log' returned non-zero exit status 2.

During handling of the above exception, another exception occurred:

Traceback (most recent call last):
  File "/home/lucianhu/micromamba/envs/rna_snakemake/lib/python3.12/site-packages/snakemake/executors/local.py", line 261, in _callback
    raise ex
  File "/home/lucianhu/micromamba/envs/rna_snakemake/lib/python3.12/concurrent/futures/thread.py", line 58, in run
    result = self.fn(*self.args, **self.kwargs)
             ^^^^^^^^^^^^^^^^^^^^^^^^^^^^^^^^^^
  File "/home/lucianhu/micromamba/envs/rna_snakemake/lib/python3.12/site-packages/snakemake/executors/local.py", line 247, in cached_or_run
    run_func(*args)
  File "/home/lucianhu/micromamba/envs/rna_snakemake/lib/python3.12/site-packages/snakemake/executors/local.py", line 459, in run_wrapper
    raise RuleException(
snakemake.exceptions.RuleException: CalledProcessError in file /home/lucianhu/rna_snakemake/test_ting/Snakefile, line 237:
Command 'set -euo pipefail;  
        fastqc --quiet --threads 6 /home/lucianhu/rna_snakemake/rna_snakemake/test-datasets/testdata/SRR6357073_1.fastq.gz          --outdir results/fastqc/RAP1_REP1_treatment &> logs/fastqc/RAP1_REP1_treatment.fastqc.log' returned non-zero exit status 2.

RuleException:
CalledProcessError in file /home/lucianhu/rna_snakemake/test_ting/Snakefile, line 237:
Command 'set -euo pipefail;  
        fastqc --quiet --threads 6 /home/lucianhu/rna_snakemake/rna_snakemake/test-datasets/testdata/SRR6357073_1.fastq.gz          --outdir results/fastqc/RAP1_REP1_treatment &> logs/fastqc/RAP1_REP1_treatment.fastqc.log' returned non-zero exit status 2.
[Sun Aug 18 22:42:06 2024]
Error in rule fastqc:
    jobid: 4
    input: /home/lucianhu/rna_snakemake/rna_snakemake/test-datasets/testdata/SRR6357073_1.fastq.gz
    output: results/fastqc/RAP1_REP1_treatment
    log: logs/fastqc/RAP1_REP1_treatment.fastqc.log (check log file(s) for error details)
    conda-env: /home/lucianhu/rna_snakemake/test_ting/.snakemake/conda/6560e655f15db8ccf0d5611fa7df93d1_
    shell:
        
        fastqc --quiet --threads 6 /home/lucianhu/rna_snakemake/rna_snakemake/test-datasets/testdata/SRR6357073_1.fastq.gz          --outdir results/fastqc/RAP1_REP1_treatment &> logs/fastqc/RAP1_REP1_treatment.fastqc.log
        
        (one of the commands exited with non-zero exit code; note that snakemake uses bash strict mode!)

Shutting down, this might take some time.
Exiting because a job execution failed. Look above for error message
Complete log: .snakemake/log/2024-08-18T224206.085603.snakemake.log
unlocking
removing lock
removing lock
removed all locks
Full Traceback (most recent call last):
  File "/home/lucianhu/micromamba/envs/rna_snakemake/lib/python3.12/site-packages/snakemake/cli.py", line 2103, in args_to_api
    dag_api.execute_workflow(
  File "/home/lucianhu/micromamba/envs/rna_snakemake/lib/python3.12/site-packages/snakemake/api.py", line 594, in execute_workflow
    workflow.execute(
  File "/home/lucianhu/micromamba/envs/rna_snakemake/lib/python3.12/site-packages/snakemake/workflow.py", line 1286, in execute
    raise WorkflowError("At least one job did not complete successfully.")
snakemake_interface_common.exceptions.WorkflowError: At least one job did not complete successfully.

WorkflowError:
At least one job did not complete successfully.
